package Exception_handling;

public class Exception_Handling_Methods {

	public static void main(String args[]) 
	{
		method1();
		arithmetic_exce1();
		arithmetic_exce2();
		array_ind_outof_bound_exce();
		method2();
	}

	//if you don't handle the exception, the statements fall after your exception will not get executed.
	//Throwable is a super class which absorbs all the Errors and Exception.
	//To further narrow down to handle the exceptions, you can use the subclass of Exception. 
		//for example: "ArithmeticException" instead of "Exception" or "Throwable"
	//In a sequence, If you catch ArithmeticException, execution will not go further to Exception or to further Throwable to catch.
	//In a sequence, If you catch exception with Throwable, execution will not go further as Throwable absorbs all exceptions.
	

	public static void method1()
	{
		try {
				System.out.println("Executing Method1...");
			}catch(Throwable e) {};
	
	}

	public static void arithmetic_exce1() 
	{
		try {
				int i = 100 / 0;
				System.out.println(i);
			}catch(Exception e) 
			{
				//System.out.println(e.getMessage());
				e.printStackTrace();
			}
	}
	//This is same as above method, but the execution stopped at line 47 and did not went to 51 like in above method
	public static void arithmetic_exce2() 
	{
		try {
				int i = 100 / 0;
				System.out.println(i);
			}catch(ArithmeticException e) 
			{
				e.printStackTrace();
				
			}catch(Exception e)
			{
				e.printStackTrace();
			}catch(Throwable e)
			{
				e.printStackTrace();
			}
	}
	
	public static void array_ind_outof_bound_exce() 
	{
		try {
			
			int[] arrInt = {1,2,3};
			System.out.println(arrInt[5]);
			
		}catch(ArrayIndexOutOfBoundsException e) 
		{
			e.printStackTrace();
		}
		

	}

	public static void method2()
	{
		try {
				System.out.println("Executing Method2...");
			}catch(Exception e) {}
	}
}